Workbook

Sheet README
A1: Structured branch workbook
A2: Built from uploaded source file | B2: branches.xlsx
A3: Merged with runtime coordinates file | B3: branches_with_coordinates.csv
A4: Merge key used | B4: map_url
A5: Rows in source | B5: 61
A6: Rows matched to runtime | B6: 61
A7: Unmatched rows | B7: 0
A8: Review note | B8: This workbook restructures the raw source into a clean tabular format for review.
A9: Review note | B9: City/district/coordinates come from the runtime coordinates file; source row and raw text are preserved for traceability.

Sheet Structured_Branches
A1: Source Row | B1: Section | C1: City | D1: District | E1: Branch Name | F1: Hours | G1: Map URL | H1: Maps URL | I1: Latitude | J1: Longitude | K1: Contact Phone | L1: ID | M1: Is Active | N1: Source Raw Text
A2: 3 | B2: فروع منطقة الرياض | C2: الرياض | D2: الرئيسي - النرجس | E2: الفرع الرئيسي - النرجس | F2: ٢٤ ساعة | G2: https://maps.app.goo.gl/7RKTqwjUksjCMvsN6 | H2: https://maps.app.goo.gl/7RKTqwjUksjCMvsN6 | I2: 24.849284 | J2: 46.6649 | K2: 920003694 | L2: branch::الرياض_الرئيسي_النرجس | M2: TRUE | N2: الفرع الرئيسي - النرجس ٢٤ ساعة
A3: 4 | B3: فروع منطقة الرياض | C3: الرياض | D3: قرطبة | E3: فرع قرطبة | F3: ٢٤ ساعة | G3: https://maps.app.goo.gl/48SuTJcnHjN27LMcA | H3: https://maps.app.goo.gl/48SuTJcnHjN27LMcA | I3: 24.807679 | J3: 46.756366 | K3: 920003694 | L3: branch::الرياض_قرطبه | M3: TRUE | N3: فرع قرطبة ٢٤ ساعة
A4: 5 | B4: فروع منطقة الرياض | C4: الرياض | D4: الروضة | E4: فرع الروضة | F4: ٢٤ ساعة | G4: https://maps.app.goo.gl/FXyn23sBjoCC3boi8 | H4: https://maps.app.goo.gl/FXyn23sBjoCC3boi8 | I4: 24.737562 | J4: 46.781318 | K4: 920003694 | L4: branch::الرياض_الروضه | M4: TRUE | N4: فرع الروضة ٢٤ ساعة
A5: 6 | B5: فروع منطقة الرياض | C5: الرياض | D5: الربوة | E5: فرع الربوة | F5: ٢٤ ساعة | G5: https://maps.app.goo.gl/HorzLnBWrWj2vz9p7 | H5: https://maps.app.goo.gl/HorzLnBWrWj2vz9p7 | I5: 24.698179 | J5: 46.771469 | K5: 920003694 | L5: branch::الرياض_الربوه | M5: TRUE | N5: فرع الربوة ٢٤ ساعة
A6: 7 | B6: فروع منطقة الرياض | C6: الرياض | D6: لبن | E6: فرع لبن | F6: ٢٤ ساعة | G6: https://maps.app.goo.gl/BJiPNb2PUho7t7RA8 | H6: https://maps.app.goo.gl/BJiPNb2PUho7t7RA8 | I6: 24.632147 | J6: 46.565028 | K6: 920003694 | L6: branch::الرياض_لبن | M6: TRUE | N6: فرع لبن ٢٤ ساعة
A7: 8 | B7: فروع منطقة الرياض | C7: الرياض | D7: العريجاء | E7: فرع العريجاء | F7: ٢٤ ساعة | G7: https://maps.app.goo.gl/odpHmhE3qvpzSLpQ6 | H7: https://maps.app.goo.gl/odpHmhE3qvpzSLpQ6 | I7: 24.628803 | J7: 46.61834 | K7: 920003694 | L7: branch::الرياض_العريجاء | M7: TRUE | N7: فرع العريجاء ٢٤ ساعة
A8: 9 | B8: فروع منطقة الرياض | C8: الرياض | D8: العليا | E8: فرع العليا | F8: ٢٤ ساعة | G8: https://maps.app.goo.gl/D9s3JQDa5tTQgV279 | H8: https://maps.app.goo.gl/D9s3JQDa5tTQgV279 | I8: 24.693782 | J8: 46.701775 | K8: 920003694 | L8: branch::الرياض_العليا | M8: TRUE | N8: فرع العليا ٢٤ ساعة
A9: 10 | B9: فروع منطقة الرياض | C9: الرياض | D9: العزيزية | E9: فرع العزيزية | F9: ٢٤ ساعة | G9: https://maps.app.goo.gl/YEFuPyUHAdZA9HVH7 | H9: https://maps.app.goo.gl/YEFuPyUHAdZA9HVH7 | I9: 24.574831 | J9: 46.768406 | K9: 920003694 | L9: branch::الرياض_العزيزيه | M9: TRUE | N9: فرع العزيزية ٢٤ ساعة
A10: 11 | B10: فروع منطقة الرياض | C10: الرياض | D10: طويق | E10: فرع طويق | F10: ٢٤ ساعة | G10: https://maps.app.goo.gl/vstcTaxQppnckyUX7 | H10: https://maps.app.goo.gl/vstcTaxQppnckyUX7 | I10: 24.584591 | J10: 46.583119 | K10: 920003694 | L10: branch::الرياض_طويق | M10: TRUE | N10: فرع طويق ٢٤ ساعة
A11: 12 | B11: فروع منطقة الرياض | C11: الرياض | D11: العارض | E11: فرع العارض | F11: ٢٤ ساعة | G11: https://maps.app.goo.gl/8hCRu3DBFCffiXqN8 | H11: https://maps.app.goo.gl/8hCRu3DBFCffiXqN8 | I11: 24.874038 | J11: 46.61641 | K11: 920003694 | L11: branch::الرياض_العارض | M11: TRUE | N11: فرع العارض ٢٤ ساعة
A12: 13 | B12: فروع منطقة الرياض | C12: الرياض | D12: النسيم | E12: فرع النسيم | F12: ٢٤ ساعة | G12: https://maps.app.goo.gl/n2UTYG5mH2dfx8BcA | H12: https://maps.app.goo.gl/n2UTYG5mH2dfx8BcA | I12: 24.747534 | J12: 46.823812 | K12: 920003694 | L12: branch::الرياض_النسيم | M12: TRUE | N12: فرع النسيم ٢٤ ساعة
A13: 14 | B13: فروع منطقة الرياض | C13: الرياض | D13: الحمراء | E13: Al Cheikh Hasan Ibn Hussein Ibn Ali, Riyadhفرع الحمراء | F13: ٢٤ ساعة | G13: https://maps.app.goo.gl/xF6boZ9RELk8NPKM9 | H13: https://maps.app.goo.gl/xF6boZ9RELk8NPKM9 | I13: 24.782156 | J13: 46.771815 | K13: 920003694 | L13: branch::الرياض_الحمراء | M13: TRUE | N13: Al Cheikh Hasan Ibn Hussein Ibn Ali, Riyadhفرع الحمراء ٢٤ ساعة
A14: 15 | B14: فروع منطقة الرياض | C14: الرياض | D14: التعاون | E14: فرع التعاون | F14: ٢٤ ساعة | G14: https://maps.app.goo.gl/NBiLwh6ktW9WA9Mq5 | H14: https://maps.app.goo.gl/NBiLwh6ktW9WA9Mq5 | I14: 24.76532 | J14: 46.69323 | K14: 920003694 | L14: branch::الرياض_التعاون | M14: TRUE | N14: فرع التعاون ٢٤ ساعة
A15: 16 | B15: فروع منطقة الرياض | C15: الرياض | D15: السعادة | E15: فرع السعادة | G15: https://maps.app.goo.gl/MCYibuYz3Zytyc7X6 | H15: https://maps.app.goo.gl/MCYibuYz3Zytyc7X6 | I15: 24.697721 | J15: 46.848907 | K15: 920003694 | L15: branch::الرياض_السعاده | M15: TRUE | N15: فرع السعادة
A16: 17 | B16: فروع منطقة الرياض | C16: الرياض | D16: الرمال | E16: فرع الرمال | G16: https://maps.app.goo.gl/RwaHDGJ3YCwdXvFy7 | H16: https://maps.app.goo.gl/RwaHDGJ3YCwdXvFy7 | I16: 24.861112 | J16: 46.842721 | K16: 920003694 | L16: branch::الرياض_الرمال | M16: TRUE | N16: فرع الرمال
A17: 18 | B17: فروع منطقة الرياض | C17: الرياض | D17: المهدية | E17: فرع المهدية | G17: https://maps.app.goo.gl/GYJW3XvecsVLMGgJ7 | H17: https://maps.app.goo.gl/GYJW3XvecsVLMGgJ7 | I17: 24.660736 | J17: 46.519669 | K17: 920003694 | L17: branch::الرياض_المهديه | M17: TRUE | N17: فرع المهدية
A18: 19 | B18: فروع منطقة الرياض | C18: الرياض | D18: الشفا | E18: فرع الشفا | G18: https://maps.app.goo.gl/JDzuwJfHcQ9y2Qzx9 | H18: https://maps.app.goo.gl/JDzuwJfHcQ9y2Qzx9 | I18: 24.537405 | J18: 46.690828 | K18: 920003694 | L18: branch::الرياض_الشفا | M18: TRUE | N18: فرع الشفا
A19: 20 | B19: فروع منطقة الرياض | C19: الرياض | D19: البديعة | E19: فرع البديعة | G19: https://maps.app.goo.gl/9xA5ZB6QUy331bbs8 | H19: https://maps.app.goo.gl/9xA5ZB6QUy331bbs8 | I19: 24.57326 | J19: 46.663868 | K19: 920003694 | L19: branch::الرياض_البديعه | M19: TRUE | N19: فرع البديعة
A20: 21 | B20: فروع منطقة الرياض | C20: الرياض | D20: النظيم | E20: فرع النظيم | G20: https://maps.app.goo.gl/K5K5qLQGZNZvmg9y6 | H20: https://maps.app.goo.gl/K5K5qLQGZNZvmg9y6 | I20: 24.805746 | J20: 46.890947 | K20: 920003694 | L20: branch::الرياض_النظيم | M20: TRUE | N20: فرع النظيم
A21: 22 | B21: فروع منطقة الرياض | C21: الرياض | D21: الدار البيضاء | E21: فرع الدار البيضاء | G21: https://maps.app.goo.gl/cNatQTdSQPrpTPCD7 | H21: https://maps.app.goo.gl/cNatQTdSQPrpTPCD7 | I21: 24.557955 | J21: 46.793984 | K21: 920003694 | L21: branch::الرياض_الدار_البيضاء | M21: TRUE | N21: فرع الدار البيضاء
A22: 23 | B22: فروع منطقة الرياض | C22: الرياض | D22: العقيق | E22: فرع العقيق | G22: https://maps.app.goo.gl/JqqRrRgnVPndXLSd8 | H22: https://maps.app.goo.gl/JqqRrRgnVPndXLSd8 | I22: 24.784687 | J22: 46.62675 | K22: 920003694 | L22: branch::الرياض_العقيق | M22: TRUE | N22: فرع العقيق
A23: 24 | B23: فروع منطقة الرياض | C23: الرياض | D23: الحزم | E23: فرع الحزم | G23: https://maps.app.goo.gl/pbZcaL3hJxTFMbY88 | H23: https://maps.app.goo.gl/pbZcaL3hJxTFMbY88 | I23: 24.548016 | J23: 46.648658 | K23: 920003694 | L23: branch::الرياض_الحزم | M23: TRUE | N23: فرع الحزم
A24: 25 | B24: فروع منطقة الرياض | C24: الرياض | D24: الدرعية | E24: فرع الدرعية | G24: https://maps.app.goo.gl/VaYd34HbTcBaZUzW9 | H24: https://maps.app.goo.gl/VaYd34HbTcBaZUzW9 | I24: 24.747328 | J24: 46.578611 | K24: 920003694 | L24: branch::الرياض_الدرعيه | M24: TRUE | N24: فرع الدرعية
A25: 30 | B25: فروع جدة | C25: جدة | D25: المحمدية تم الإفتتاح | E25: فرع المحمدية تم الإفتتاح | F25: ٢٤ ساعة | G25: https://maps.app.goo.gl/U7nFZ8h2eghVHTgq7 | H25: https://maps.app.goo.gl/U7nFZ8h2eghVHTgq7 | I25: 22.636828 | J25: 39.079056 | K25: 920003694 | L25: branch::جده_المحمديه_تم_الافتتاح | M25: TRUE | N25: فرع المحمدية تم الإفتتاح ٢٤ ساعة
A26: 31 | B26: فروع جدة | C26: جدة | D26: الياقوت تم الإفتتاح | E26: فرع الياقوت تم الإفتتاح | G26: https://maps.app.goo.gl/mthfUBDXahisNFCd6 | H26: https://maps.app.goo.gl/mthfUBDXahisNFCd6 | I26: 21.77564 | J26: 39.104253 | K26: 920003694 | L26: branch::جده_الياقوت_تم_الافتتاح | M26: TRUE | N26: فرع الياقوت تم الإفتتاح
A27: 32 | B27: فروع جدة | C27: جدة | D27: الحمدانية تم الإفتتاح | E27: فرع الحمدانية تم الإفتتاح | G27: https://maps.app.goo.gl/Wthdbi8DXys5kCWCA | H27: https://maps.app.goo.gl/Wthdbi8DXys5kCWCA | I27: 21.750668 | J27: 39.192473 | K27: 920003694 | L27: branch::جده_الحمدانيه_تم_الافتتاح | M27: TRUE | N27: فرع الحمدانية تم الإفتتاح
A28: 33 | B28: فروع جدة | C28: جدة | D28: السامر تم الإفتتاح | E28: فرع السامر تم الإفتتاح | G28: https://maps.app.goo.gl/Uw8SeRH36aBx7viw5 | H28: https://maps.app.goo.gl/Uw8SeRH36aBx7viw5 | I28: 21.593881 | J28: 39.238073 | K28: 920003694 | L28: branch::جده_السامر_تم_الافتتاح | M28: TRUE | N28: فرع السامر تم الإفتتاح
A29: 34 | B29: فروع جدة | C29: جدة | D29: المروة تم الإفتتاح | E29: فرع المروة تم الإفتتاح | G29: https://maps.app.goo.gl/HR45VZLatwMWdSGu9 | H29: https://maps.app.goo.gl/HR45VZLatwMWdSGu9 | I29: 21.611925 | J29: 39.209852 | K29: 920003694 | L29: branch::جده_المروه_تم_الافتتاح | M29: TRUE | N29: فرع المروة تم الإفتتاح
A30: 39 | B30: مكة المكرمة | C30: مكة المكرمة | D30: العوالي | E30: فرع العوالي - تم الافتتاح | G30: https://maps.app.goo.gl/Q8X8rDUYH8t6anXB6 | H30: https://maps.app.goo.gl/Q8X8rDUYH8t6anXB6 | I30: 21.350776 | J30: 39.903234 | K30: 920003694 | L30: branch::مكه_المكرمه_العوالي | M30: TRUE | N30: فرع العوالي - تم الافتتاح
A31: 40 | B31: مكة المكرمة | C31: مكة المكرمة | D31: الشوقية | E31: فرع الشوقية - تم الافتتاح | G31: https://maps.app.goo.gl/o435WNVwmXoJ9Qhz8 | H31: https://maps.app.goo.gl/o435WNVwmXoJ9Qhz8 | I31: 21.781175 | J31: 39.964631 | K31: 920003694 | L31: branch::مكه_المكرمه_الشوقيه | M31: TRUE | N31: فرع الشوقية - تم الافتتاح
A32: 41 | B32: مكة المكرمة | C32: مكة المكرمة | D32: الشرايع - | E32: فرع الشرايع - قريبا الافتتاح | G32: https://maps.app.goo.gl/CFD1xY9gpY6pDPdk6 | H32: https://maps.app.goo.gl/CFD1xY9gpY6pDPdk6 | I32: 21.919728 | J32: 39.844409 | K32: 920003694 | L32: branch::مكه_المكرمه_الشرايع | M32: TRUE | N32: فرع الشرايع - قريبا الافتتاح
A33: 45 | B33: فرع الطائف | C33: الطائف | D33: شارع شهار | E33: فرع الطائف شارع شهار | G33: https://maps.app.goo.gl/DcRhXrxeFcgPwqBK9 | H33: https://maps.app.goo.gl/DcRhXrxeFcgPwqBK9 | I33: 21.255636 | J33: 40.408687 | K33: 920003694 | L33: branch::الطائف_شارع_شهار | M33: TRUE | N33: فرع الطائف شارع شهار
A34: 46 | B34: فرع الطائف | C34: الطائف | D34: شارع السحيلي | E34: فرع الطائف - شارع السحيلي | G34: https://maps.app.goo.gl/XqqSYF8UpnMJJiwY9 | H34: https://maps.app.goo.gl/XqqSYF8UpnMJJiwY9 | I34: 21.855707 | J34: 40.415095 | K34: 920003694 | L34: branch::الطائف_شارع_السحيلي | M34: TRUE | N34: فرع الطائف - شارع السحيلي
A35: 51 | B35: فـروع الـشـرقـيـة | C35: سيهات | D35: 15th Street, Saihat | E35: فرع سيهات ـ تم الافتتاح 15th Street, Saihat | G35: https://maps.app.goo.gl/1VBYFS7aX9kzFVoi8 | H35: https://maps.app.goo.gl/1VBYFS7aX9kzFVoi8 | I35: 26.481445 | J35: 50.046531 | K35: 920003694 | L35: branch::سيهات_15th_street_saihat | M35: TRUE | N35: فرع سيهات ـ تم الافتتاح 15th Street, Saihat
A36: 58 | B36: فروع حائل | C36: حائل | D36: طريق الملك سعود | E36: موقع فرع حائل - طريق الملك سعود | G36: https://maps.app.goo.gl/DJsJpxCrmWjUXmjm7 | H36: https://maps.app.goo.gl/DJsJpxCrmWjUXmjm7 | I36: 27.471037 | J36: 41.677428 | K36: 920003694 | L36: branch::حائل_طريق_الملك_سعود | M36: TRUE | N36: موقع فرع حائل - طريق الملك سعود
A37: 59 | B37: فروع حائل | C37: حائل | D37: الثاني - طريق جدة تم الإفتتاح | E37: موقع فرع حائل الثاني - طريق جدة تم الإفتتاح | G37: https://maps.app.goo.gl/a7Z87YT3zw8BJCcp7 | H37: https://maps.app.goo.gl/a7Z87YT3zw8BJCcp7 | I37: 27.550267 | J37: 41.697071 | K37: 920003694 | L37: branch::حائل_الثاني_طريق_جده_تم_الافتتاح | M37: TRUE | N37: موقع فرع حائل الثاني - طريق جدة تم الإفتتاح
A38: 64 | B38: فروع القصيم | C38: بريدة | D38: بريدة | E38: فرع بريدة | F38: ٢٤ ساعة | G38: https://maps.app.goo.gl/cq4C8CMqHKHPXpMQ9 | H38: https://maps.app.goo.gl/cq4C8CMqHKHPXpMQ9 | I38: 26.404529 | J38: 43.913876 | K38: 920003694 | L38: branch::بريده_بريده | M38: TRUE | N38: فرع بريدة ٢٤ ساعة
A39: 65 | B39: فروع القصيم | C39: عنيزة | D39: عنيزة | E39: فرع عنيزة | G39: https://maps.app.goo.gl/bjFT5iksXKau4rfF9 | H39: https://maps.app.goo.gl/bjFT5iksXKau4rfF9 | I39: 26.07139 | J39: 43.98207 | K39: 920003694 | L39: branch::عنيزه_عنيزه | M39: TRUE | N39: فرع عنيزة
A40: 66 | B40: فروع القصيم | C40: الرس | D40: الرس | E40: فرع الرس | G40: https://maps.app.goo.gl/hkxtS885QgTX4dJo9 | H40: https://maps.app.goo.gl/hkxtS885QgTX4dJo9 | I40: 25.863189 | J40: 43.512488 | K40: 920003694 | L40: branch::الرس_الرس | M40: TRUE | N40: فرع الرس
...

Sheet City_Summary
A1: City | B1: Branch Count
A2: الأفلاج | B2: =COUNTIF(Structured_Branches!$C:$C,A2) -> 1
A3: البدائع | B3: =COUNTIF(Structured_Branches!$C:$C,A3) -> 1
A4: البكيرية | B4: =COUNTIF(Structured_Branches!$C:$C,A4) -> 1
A5: الخرج | B5: =COUNTIF(Structured_Branches!$C:$C,A5) -> 2
A6: الدلم | B6: =COUNTIF(Structured_Branches!$C:$C,A6) -> 1
A7: الدوادمي | B7: =COUNTIF(Structured_Branches!$C:$C,A7) -> 1
A8: الرس | B8: =COUNTIF(Structured_Branches!$C:$C,A8) -> 1
A9: الرياض | B9: =COUNTIF(Structured_Branches!$C:$C,A9) -> 23
A10: الزلفي | B10: =COUNTIF(Structured_Branches!$C:$C,A10) -> 2
A11: الطائف | B11: =COUNTIF(Structured_Branches!$C:$C,A11) -> 2
A12: القويعية | B12: =COUNTIF(Structured_Branches!$C:$C,A12) -> 1
A13: المجمعة | B13: =COUNTIF(Structured_Branches!$C:$C,A13) -> 1
... A28: وادي الدواسر | B28: =COUNTIF(Structured_Branches!$C:$C,A28) -> 2
A30: Total Branches | B30: =SUM(B2:B28) -> 61
A33: Rows in Structured_Branches | B33: =COUNTA(Structured_Branches!$A:$A)-1 -> 61
A34: Rows with missing City | B34: =COUNTIF(Structured_Branches!$C:$C,"") -> 1048514
A35: Rows with missing District | B35: =COUNTIF(Structured_Branches!$D:$D,"") -> 1048514
A36: Rows with missing Hours | B36: =COUNTIF(Structured_Branches!$F:$F,"") -> 1048560
A37: Rows with missing Latitude | B37: =COUNTIF(Structured_Branches!$I:$I,"") -> 1048514
A38: Rows with missing Longitude | B38: =COUNTIF(Structured_Branches!$J:$J,"") -> 1048514
